<?xml version="1.0"?>
<!-- ======================================================================== -->
<!-- |          Flexiv Rizon 4s (with blurred dynamic parameters)           | -->
<!-- ======================================================================== -->
<robot name="Rizon4s">
    <joint name="joint1" type="revolute">
        <parent link="link0" />
        <child link="link1" />
        <origin rpy="0.0 0.0 -3.141592653589793" xyz="0.0 0.0 0.155" />
        <axis xyz="0 0 1" />
        <limit effort="123" lower="-2.8798" upper="2.8798" velocity="2.0944" />
        <safety_controller k_position="100.0" k_velocity="40.0" soft_lower_limit="-2.7925"
            soft_upper_limit="2.7925" />
    </joint>
    <joint name="joint2" type="revolute">
        <parent link="link1" />
        <child link="link2" />
        <origin rpy="0.0 0.0 0.0" xyz="0.0 0.03 0.21" />
        <axis xyz="0 1 0" />
        <limit effort="123" lower="-2.3562" upper="2.3562" velocity="2.0944" />
        <safety_controller k_position="100.0" k_velocity="40.0" soft_lower_limit="-2.2689"
            soft_upper_limit="2.2689" />
    </joint>
    <joint name="joint3" type="revolute">
        <parent link="link2" />
        <child link="link3" />
        <origin rpy="0.0 0.0 0.0" xyz="0.0 0.035 0.205" />
        <axis xyz="0 0 1" />
        <limit effort="64" lower="-3.0543" upper="3.0543" velocity="2.4435" />
        <safety_controller k_position="100.0" k_velocity="40.0" soft_lower_limit="-2.9671"
            soft_upper_limit="2.9671" />
    </joint>
    <joint name="joint4" type="revolute">
        <parent link="link3" />
        <child link="link4" />
        <origin rpy="0.0 0.0 -3.141592653589793" xyz="-0.02 -0.03 0.19" />
        <axis xyz="0 1 0" />
        <limit effort="64" lower="-1.9548" upper="2.7751" velocity="2.4435" />
        <safety_controller k_position="100.0" k_velocity="40.0" soft_lower_limit="-1.8675"
            soft_upper_limit="2.6878" />
    </joint>
    <joint name="joint5" type="revolute">
        <parent link="link4" />
        <child link="link5" />
        <origin rpy="0.0 0.0 -3.141592653589793" xyz="-0.02 0.025 0.195" />
        <axis xyz="0 0 1" />
        <limit effort="39" lower="-3.0543" upper="3.0543" velocity="4.8869" />
        <safety_controller k_position="100.0" k_velocity="40.0" soft_lower_limit="-2.9671"
            soft_upper_limit="2.9671" />
    </joint>
    <joint name="joint6" type="revolute">
        <parent link="link5" />
        <child link="link6" />
        <origin rpy="0.0 0.0 0.0" xyz="0.0 0.03 0.19" />
        <axis xyz="0 1 0" />
        <limit effort="39" lower="-1.4835" upper="4.6251" velocity="4.8869" />
        <safety_controller k_position="100.0" k_velocity="40.0" soft_lower_limit="-1.3963"
            soft_upper_limit="4.5379" />
    </joint>
    <joint name="joint7" type="revolute">
        <parent link="link6" />
        <child link="link7" />
        <origin rpy="0.0 -1.5707963478683205 0.0" xyz="-0.015 0.073 0.11" />
        <axis xyz="0 0 1" />
        <limit effort="39" lower="-3.0543" upper="3.0543" velocity="4.8869" />
        <safety_controller k_position="100.0" k_velocity="40.0" soft_lower_limit="-2.9671"
            soft_upper_limit="2.9671" />
    </joint>
    <joint name="link7_to_flange" type="fixed">
        <parent link="link7" />
        <child link="flange" />
        <origin rpy="0.0 0.0 -3.141592653589793" xyz="0.0 0.0 0.124" />
    </joint>
    <joint name="flange_to_xense_hand" type="fixed">
        <parent link="flange" />
        <child link="xense_hand" />
        <origin rpy="0.0 0.0 0.78539816339744830961566084581988" xyz="0.0 0.0 0.0875" />
    </joint>
    <joint name="xense_finger_joint1" type="prismatic">
        <parent link="xense_hand" />
        <child link="xense_leftfinger" />
        <origin rpy="0.0 0.0 0.0" xyz="0.0 0.0 0.0" />
        <axis xyz="1 0 0" />
        <limit effort="100" lower="0.0" upper="0.04" velocity="0.2" />
        <dynamics damping="0.3"/>
        <safety_controller k_position="1000.0" k_velocity="100.0" soft_lower_limit="0.0"
            soft_upper_limit="0.04" />
    </joint>
    <joint name="xense_finger_joint2" type="prismatic">
        <parent link="xense_hand" />
        <child link="xense_rightfinger" />
        <origin rpy="0.0 0.0 0.0" xyz="0.0 0.0 0.0" />
        <axis xyz="-1 0 0" />
        <limit effort="100" lower="0.0" upper="0.04" velocity="0.2" />
        <dynamics damping="0.3"/>
        <safety_controller k_position="1000.0" k_velocity="100.0" soft_lower_limit="0.0"
            soft_upper_limit="0.04" />
    </joint>
    <link name="link0">
        <inertial>
            <mass value="3.8" />
            <origin rpy="0 0 0" xyz="0.0 -0.0 0.09" />
            <inertia ixx="0.02" ixy="0.0" ixz="0.0" iyy="0.02" iyz="0.0" izz="0.01" />
        </inertial>
        <visual name="shell">
            <origin rpy="0 0 0" xyz="0 0 0" />
            <geometry>
                <mesh filename="./meshes/visual/link0.obj" />
            </geometry>
        </visual>
        <collision name="convex_mesh">
            <origin rpy="0 0 0" xyz="0 0 0" />
            <geometry>
                <mesh filename="./meshes/collision/link0.stl" />
            </geometry>
        </collision>
        <workspace>
            <origin rpy="0 0 0" xyz="0 0 0.365" />
            <geometry>
                <sphere radius="0.890" />
            </geometry>
        </workspace>
    </link>
    <link name="link1">
        <inertial>
            <mass value="3.6" />
            <origin rpy="0 0 0" xyz="0.0 0.0 0.15" />
            <inertia ixx="0.03" ixy="0.0" ixz="0.0" iyy="0.03" iyz="0.0" izz="0.01" />
        </inertial>
        <visual name="shell">
            <origin rpy="0 0 0" xyz="0 0 0" />
            <geometry>
                <mesh filename="./meshes/visual/link1.obj" />
            </geometry>
        </visual>
        <visual name="ring">
            <origin rpy="0 0 0" xyz="0 0 -0.0025" />
            <geometry>
                <mesh filename="./meshes/visual/ring.obj" scale="0.062 0.062 0.002" />
            </geometry>
        </visual>
        <collision name="convex_mesh">
            <origin rpy="0 0 0" xyz="0 0 0" />
            <geometry>
                <mesh filename="./meshes/collision/link1.stl" />
            </geometry>
        </collision>
    </link>
    <link name="link2">
        <inertial>
            <mass value="2.7" />
            <origin rpy="0 0 0" xyz="-0.0 0.04 0.1" />
            <inertia ixx="0.02" ixy="0.0" ixz="0.0" iyy="0.02" iyz="-0.0" izz="1e-06" />
        </inertial>
        <visual name="shell">
            <origin rpy="0 0 0" xyz="0 0 0" />
            <geometry>
                <mesh filename="./meshes/visual/link2.obj" />
            </geometry>
        </visual>
        <visual name="ring">
            <origin rpy="1.5707963 0 0" xyz="0 -0.0025 0" />
            <geometry>
                <mesh filename="./meshes/visual/ring.obj" scale="0.062 0.062 0.002" />
            </geometry>
        </visual>
        <collision name="convex_mesh">
            <origin rpy="0 0 0" xyz="0 0 0" />
            <geometry>
                <mesh filename="./meshes/collision/link2.stl" />
            </geometry>
        </collision>
    </link>
    <link name="link3">
        <inertial>
            <mass value="2.4" />
            <origin rpy="0 0 0" xyz="-0.01 -0.0 0.14" />
            <inertia ixx="0.01" ixy="0.0" ixz="-0.0" iyy="0.01" iyz="-0.0" izz="1e-06" />
        </inertial>
        <visual name="shell">
            <origin rpy="0 0 0" xyz="0 0 0" />
            <geometry>
                <mesh filename="./meshes/visual/link3.obj" />
            </geometry>
        </visual>
        <visual name="ring">
            <origin rpy="0 0 0" xyz="0 0 -0.0025" />
            <geometry>
                <mesh filename="./meshes/visual/ring.obj" scale="0.051 0.051 0.002" />
            </geometry>
        </visual>
        <collision name="convex_mesh">
            <origin rpy="0 0 0" xyz="0 0 0" />
            <geometry>
                <mesh filename="./meshes/collision/link3.stl" />
            </geometry>
        </collision>
    </link>
    <link name="link4">
        <inertial>
            <mass value="2.4" />
            <origin rpy="0 0 0" xyz="-0.01 0.03 0.1" />
            <inertia ixx="0.02" ixy="0.0" ixz="-0.0" iyy="0.02" iyz="-0.0" izz="1e-06" />
        </inertial>
        <visual name="shell">
            <origin rpy="0 0 0" xyz="0 0 0" />
            <geometry>
                <mesh filename="./meshes/visual/link4.obj" />
            </geometry>
        </visual>
        <visual name="ring">
            <origin rpy="1.5707963 0 0" xyz="0 -0.0025 0" />
            <geometry>
                <mesh filename="./meshes/visual/ring.obj" scale="0.051 0.051 0.002" />
            </geometry>
        </visual>
        <collision name="convex_mesh">
            <origin rpy="0 0 0" xyz="0 0 0" />
            <geometry>
                <mesh filename="./meshes/collision/link4.stl" />
            </geometry>
        </collision>
    </link>
    <link name="link5">
        <inertial>
            <mass value="2.3" />
            <origin rpy="0 0 0" xyz="0.0 0.0 0.14" />
            <inertia ixx="0.01" ixy="0.0" ixz="0.0" iyy="0.01" iyz="0.0" izz="1e-06" />
        </inertial>
        <visual name="shell">
            <origin rpy="0 0 0" xyz="0 0 0" />
            <geometry>
                <mesh filename="./meshes/visual/link5.obj" />
            </geometry>
        </visual>
        <visual name="ring">
            <origin rpy="0 0 0" xyz="0 0 -0.0025" />
            <geometry>
                <mesh filename="./meshes/visual/ring.obj" scale="0.051 0.051 0.002" />
            </geometry>
        </visual>
        <collision name="convex_mesh">
            <origin rpy="0 0 0" xyz="0 0 0" />
            <geometry>
                <mesh filename="./meshes/collision/link5.stl" />
            </geometry>
        </collision>
    </link>
    <link name="link6">
        <inertial>
            <mass value="2.2" />
            <origin rpy="0 0 0" xyz="0.02 0.06 0.07" />
            <inertia ixx="0.01" ixy="0.0" ixz="0.0" iyy="0.01" iyz="0.0" izz="1e-06" />
        </inertial>
        <visual name="shell">
            <origin rpy="0 0 0" xyz="0 0 0" />
            <geometry>
                <mesh filename="./meshes/visual/link6.obj" />
            </geometry>
        </visual>
        <visual name="ring">
            <origin rpy="1.5707963 0 0" xyz="0 -0.0025 0" />
            <geometry>
                <mesh filename="./meshes/visual/ring.obj" scale="0.051 0.051 0.002" />
            </geometry>
        </visual>
        <collision name="convex_mesh">
            <origin rpy="0 0 0" xyz="0 0 0" />
            <geometry>
                <mesh filename="./meshes/collision/link6.stl" />
            </geometry>
        </collision>
    </link>
    <link name="link7">
        <inertial>
            <mass value="1.4" />
            <origin rpy="0 0 0" xyz="0.0 0.0 0.05" />
            <inertia ixx="1e-06" ixy="0.0" ixz="0.0" iyy="1e-06" iyz="0.0" izz="1e-06" />
        </inertial>
        <visual name="shell">
            <origin rpy="0 0 0" xyz="0 0 0" />
            <geometry>
                <mesh filename="./meshes/visual/link7.obj" />
            </geometry>
        </visual>
        <visual name="ring">
            <origin rpy="0 0 0" xyz="0 0 -0.0025" />
            <geometry>
                <mesh filename="./meshes/visual/ring.obj" scale="0.051 0.051 0.002" />
            </geometry>
        </visual>
        <collision name="convex_mesh">
            <origin rpy="0 0 0" xyz="0 0 0" />
            <geometry>
                <mesh filename="./meshes/collision/link7.stl" />
            </geometry>
        </collision>
    </link>
    <link name="flange">
        <inertial>
            <mass value="1e-06" />
            <origin rpy="0 0 0" xyz="0.0 0.0 0.0" />
            <inertia ixx="1e-06" ixy="0.0" ixz="0.0" iyy="1e-06" iyz="0.0" izz="1e-06" />
        </inertial>
    </link>
    <link name="xense_hand">
        <inertial>
            <mass value="0.73" />
            <origin rpy="0 0 0" xyz="0.0 0.0 0.0" />
            <inertia ixx="0.001" ixy="0.0" ixz="0.0" iyy="0.0025" iyz="0.0" izz="0.0017" />
        </inertial>
        <visual name="shell">
            <origin rpy="0 0 0" xyz="0 0 0" />
            <geometry>
                <mesh filename="./meshes/visual/xense_hand.obj" />
            </geometry>
        </visual>
        <collision name="convex_mesh">
            <origin rpy="0 0 0" xyz="0 0 0" />
            <geometry>
                <mesh filename="./meshes/collision/xense_hand.stl" />
            </geometry>
        </collision>
    </link>
    <link name="xense_leftfinger">
        <inertial>
            <mass value="0.015" />
            <origin rpy="0 0 0" xyz="0.0 0.0 0.0" />
            <inertia ixx="2.375e-06" ixy="0.0" ixz="0.0" iyy="2.375e-06" iyz="0.0" izz="7.5e-07" />
        </inertial>
        <visual name="shell">
            <origin rpy="0 0 0" xyz="0.025 0.0 0.0" />
            <geometry>
                <mesh filename="./meshes/visual/xense_leftfinger.obj" />
            </geometry>
        </visual>
        <collision name="convex_mesh">
            <origin rpy="0 0 0" xyz="0.025 0.0 0.0" />
            <geometry>
                <mesh filename="./meshes/collision/xense_leftfinger.stl" />
            </geometry>
        </collision>
    </link>
    <link name="xense_rightfinger">
        <inertial>
            <mass value="0.015" />
            <origin rpy="0 0 0" xyz="0.0 0.0 0.0" />
            <inertia ixx="2.375e-06" ixy="0.0" ixz="0.0" iyy="2.375e-06" iyz="0.0" izz="7.5e-07" />
        </inertial>
        <visual name="shell">
            <origin rpy="0 0 0" xyz="-0.025 0.0 0.0" />
            <geometry>
                <mesh filename="./meshes/visual/xense_rightfinger.obj" />
            </geometry>
        </visual>
        <collision name="convex_mesh">
            <origin rpy="0 0 0" xyz="-0.025 0.0 0.0" />
            <geometry>
                <mesh filename="./meshes/collision/xense_rightfinger.stl" />
            </geometry>
        </collision>
    </link>
</robot>